Workbook

Sheet INGRESOS FIJOS
A1: INGRESOS FIJOS MENSUALES MES VENCIDO | B1: 46204 | C1: 46235 | D1: 46266 | E1: 46296 | F1: 46327 | G1: 46357 | H1: TOTAL AÑO
A2: Sueldo pago Proaguas | B2: =828.19 -> 828.19 | C2: 0 | D2: 1195.65 | E2: 2300 | F2: 2300 | G2: 2300 | H2: =SUM(B2:G2) -> 8923.84
A3: Sueldo Seguridad social paternidad | B3: 1613.97 | C3: 2633.45 | D3: 1104.35 | E3: 0 | F3: 0 | G3: 0 | H3: =SUM(B3:G3) -> 5351.77
A4: IMV (Ingreso Mínimo Vital) -- Cuenta con efecto del 04/05/2026 CUENTA MELANIE | B4: 0 | C4: 1242 | D4: 310.5 | E4: 350.1 | F4: 350.1 | G4: 350.1 | H4: =SUM(B4:G4) -> 2602.8
A5: Devolución IRPF 2025 (puntual) (Aun no esta ingresado) | E5: 5867.11 | H5: =SUM(B5:G5) -> 5867.11
A6: **TOTAL INGRESOS** | B6: =SUM(B2:B4) -> 2442.16 | C6: =SUM(C2:C4) -> 3875.45 | D6: =SUM(D2:D4) -> 2610.5 | E6: =SUM(E2:E5) -> 8517.21 | F6: =SUM(F2:F5) -> 2650.1 | G6: =SUM(G2:G5) -> 2650.1 | H6: =SUM(H2:H5) -> 22745.52

Sheet RESUMEN GASTOS
A1: Tipo de gasto | B1: GASTOS | C1: PRESUPUESTO | D1: REAL GASTADO | E1: SOBRANTE / SOBREGASTO | F1: % CONSUMIDO
A2: Fijo | B2: GASTOS EN HIPOTECAS Y PRESTAMOS | D2: =+'GASTOS HIPOTECA-PRESTAMOS'!B5 -> 524.99
A3: Fijo | B3: GASTOS DE SEGUROS Y MUTUAS | D3: =+'GASTOS SEGUROS-MUTUAS'!D5 -> 87.02
A4: Aleatorio | B4: GASTOS DE SUPERMERCADO | C4: 400 | D4: =+'GASTOS-SUPERMERCADO'!C39 -> 539.09 | E4: =+C4-D4 -> -139.09 | F4: =+D4/$C$4 -> 1.347725
A5: Aleatorio | B5: GASTOS DE GASOLINA | C5: =+'GASTO-GASOLINA'!B17 -> 200 | D5: =+'GASTO-GASOLINA'!C17 -> 289.053 | E5: =+C5-D5 -> -89.053 | F5: =+D5/$C$5 -> 1.445265
A6: Aleatorio | B6: GASTOS DE FARMACIA | C6: 20 | D6: =+'GASTOS-SALUD'!C4 -> 19.85 | E6: =+C6-D6 -> 0.15 | F6: =+D6/$C$6 -> 0.9925
A7: Aleatorio | B7: GASTOS DE RESTAURANTE | C7: 100 | D7: =+'GASTO RESTAURANT'!C15 -> 88.75 | E7: =+C7-D7 -> 11.25 | F7: =+D7/$C$7 -> 0.8875
A8: Aleatorio | B8: GASTO DE BIENESTAR Y BELLEZA | D8: =+'GASTO BIENESTAR Y BELLEZA'!C5 -> 77
A9: Aleatorio | B9: DINERO CAJERO | D9: =+'DINERO CAJERO'!D4 -> 110
A10: Aleatorio | B10: GASTOS DE TRANSFERENCIA | D10: =+'GASTOS TRANSFERENCIAS'!D6 -> 125
A11: Aleatorio | B11: GASTOS DE ROPA Y CALZADO | D11: =+'GASTOS DE ROPA-CALZADO'!D6 -> 55.47
A12: Fijo | B12: PAGO DE TARJETA DE CREDITO PAGADO MES JULIO | D12: 382
A13: PRESTAMO | B13: PRESTAMO YAYO (TARJETA DE CREDITO) ENVIO A ECUADOR | D13: =+'GASTOS-TARJETA CREDITO'!C12 -> 874
B14: TOTAL GASTOS Y PRESTAMOS | D14: =SUM(D2:D13) -> 3172.223
B15: TOTAL GASTOS MES PROPIOS (FIJOS+ ALEATORIOS) | D15: =SUM(D2:D11) -> 1916.223
B16: TOTAL PRESPUESTO MENSUAL | D16: 1580

Sheet DINERO CAJERO
A1: FECHA | B1: SEMANA | C1: CONCEPTO | D1: IMPORTE | E1: MEDIO_PAGO | F1: TIPO
A2: 46250 | B2: Semana 2 | C2: CAJERO CAIXA OF 5694 | D2: 20 | E2: Debit | F2: GASTOS DE ENSAYO EN CALLOSA D'EN SARRIÀ
A3: 46262 | B3: Semana 4 | C3: CAJERO CAIXA OF 2251 | D3: 90 | E3: Debit | F3: PAGO DE GARAJE 45 EUROS + GARANTIA 45 EUROS
C4: TOTAL | D4: =SUM(D2:D3) -> 110

Sheet GASTOS HIPOTECA-PRESTAMOS
A1: **GASTOS FIJOS MENSUALES** | B1: 46235 | C1: 46266 | D1: 46296 | E1: 46327 | F1: 46357
A2: PRES,38384271241 (HIPOTECA) | B2: 220.57
A3: PRES,32214645963 (PRESTAMO PERSONAL) FALTAN 3 RECIBOS | B3: 56.48
A4: RECIBO PAGO PRESTAMO SANTANDER CONSUMER FINANCE (COCHE KIA STONIC) | B4: 247.94
A5: **SUBTOTAL GASTOS HIPOTECA PRESTAMO | B5: =SUM(B2:B4) -> 524.99
A6: **RECIBOS DOMICILIADOS EN BBVA* | B6: 46235 | C6: 46266 | D6: 46296 | E6: 46327 | F6: 46357
A7: Luz factura de julio (BBVA) (PAGADO POR BIZUM CUENTA FABIAN)- DINERO TRANSFERENCIA DE MELANIE | B7: 41.12
A8: Luz factura de agosto (BBVA) (PAGADO POR RECIBO DE LUZ CUENTA FABIAN) TRANFERENCIA DINERO DE MELANIE | B8: 90.24
A9: Agua (prorrateado) | B9: 0
A10: Internet + 3 móviles (CUENTA BBVA) PAGADO CON LAS TRANSFERENCIAS A MELANIE PAGO JULIO | B10: 41.63
A11: **SUBTOTAL GASTOS FIJOS** | B11: =SUM(B7:B10) -> 172.99

Sheet GASTOS-SUPERMERCADO
A1: FECHA | B1: SEMANA | C1: CONCEPTO | D1: IMPORTE | E1: MEDIO_PAGO | F1: TIPO | G1: BANCO | H1: TITULAR
A2: 46236 | B2: Semana 1 | C2: LIDL LA NUCIA | D2: 5.24 | E2: Debit | F2: Supermercado | G2: Caixa | H2: FABI
A3: 46236 | B3: Semana 1 | C3: CONSUM | D3: 10.76 | E3: Debit | F3: Supermercado | G3: Caixa | H3: FABI
A4: 46237 | B4: Semana 1 | C4: LIDL PETRER | D4: 9.21 | E4: Debit | F4: Supermercado | G4: Caixa | H4: FABI
A5: 46238 | B5: Semana 1 | C5: LIDL PETRER | D5: 25.4 | E5: Debit | F5: Supermercado | G5: Caixa | H5: FABI
A6: 46239 | B6: Semana 1 | C6: CONSUM | D6: 23.57 | E6: Debit | F6: Supermercado | G6: Caixa | H6: FABI
A7: 46240 | B7: Semana 1 | C7: LIDL PETRER | D7: 121.73 | E7: MyCard | F7: Supermercado | G7: Caixa | H7: FABI
A8: 46241 | B8: Semana 1 | C8: MARKET CANAIMA | D8: 5.3 | E8: Debit | F8: Supermercado | G8: Caixa | H8: FABI
A9: 46242 | B9: Semana 1 | C9: DIA 36126 | D9: 4.13 | E9: Debit | F9: Supermercado | G9: BBVA | H9: FABI
A10: 46244 | B10: Semana 2 | C10: MERCADONA | D10: 9.95 | E10: Debit | F10: Supermercado | G10: Caixa | H10: FABI
A11: 46244 | B11: Semana 2 | C11: MERCADONA | D11: 17.76 | E11: Debit | F11: Supermercado | G11: BBVA | H11: Mela
A12: 46246 | B12: Semana 2 | C12: DIA 1790 | D12: 13.01 | E12: Debit | F12: Supermercado | G12: Caixa | H12: FABI
A13: 46247 | B13: Semana 2 | C13: DIA 1790 | D13: 3.6 | E13: Debit | F13: Supermercado | G13: Caixa | H13: FABI
A14: 46248 | B14: Semana 2 | C14: CONSUM CALLOSA D'EN SARRIÀ | D14: 10.15 | E14: Debit | F14: Supermercado | G14: Caixa | H14: FABI
A15: 8/15/2026 | B15: Semana 2 | C15: LIDL PETRER | D15: 32.01 | E15: Debit | F15: Supermercado | G15: Caixa | H15: FABI
A16: 8/16/2026 | B16: Semana 2 | C16: LIDL LA NUCIA | D16: 21.13 | E16: Debit | F16: Supermercado | G16: Caixa | H16: FABI
A17: 8/17/2026 | B17: Semana 3 | C17: 6216 PETRER | D17: 7.85 | E17: Debit | F17: Supermercado | G17: Caixa | H17: FABI
A18: 8/18/2026 | B18: Semana 3 | C18: DIA 1790 | D18: 2.99 | E18: Debit | F18: Supermercado | G18: Caixa | H18: FABI
A19: 8/18/2026 | B19: Semana 3 | C19: LIDL SANTA POLA | D19: 10.51 | E19: Debit | F19: Supermercado | G19: Caixa | H19: FABI
A20: 8/19/2026 | B20: Semana 3 | C20: LIDL PETRER | D20: 88.62 | E20: Debit | F20: Supermercado | G20: Caixa | H20: FABI
A21: 8/20/2026 | B21: Semana 3 | C21: LIDL LA NUCIA | D21: 5.99 | E21: Debit | F21: Supermercado | G21: Caixa | H21: FABI
A22: 8/21/2026 | B22: Semana 3 | C22: LA RAISA CHUCHES | D22: 5.44 | E22: Debit | F22: Supermercado | G22: Caixa | H22: FABI
A23: 8/21/2026 | B23: Semana 3 | C23: LA RAISA CHUCHES | D23: 1.5 | E23: Debit | F23: Supermercado | G23: Caixa | H23: FABI
A24: 8/22/2026 | B24: Semana 3 | C24: LA RAISA CHUCHES | D24: 1.5 | E24: Debit | F24: Supermercado | G24: Caixa | H24: FABI
A25: 8/24/2026 | B25: Semana 4 | C25: CONSUM ELDA | D25: 22.99 | E25: Debit | F25: Supermercado | G25: Caixa | H25: FABI
A26: 8/24/2026 | B26: Semana 4 | C26: CONSUM ELDA | D26: 5.46 | E26: Debit | F26: Supermercado | G26: Caixa | H26: FABI
... A31: 8/29/2026 | B31: Semana 4 | C31: CONSUM ELDA | D31: 7.3 | E31: Debit | F31: Supermercado | G31: BBVA | H31: FABI
C32: Total (euros) | D32: =SUM(D2:D31) -> 539.09 | H32: FABI
A34: VALORACIÓN SEMANAL | B34: PRESUPUESTO | C34: GASTADO_REAL | D34: DIFERENCIA | E34: %_RENDIMIENTO | F34: ESTADO | H34: FABI
A35: Semana 1 | B35: 130 | C35: =SUMIF($B$2:$B$31,"Semana 1",$D$2:$D$31) -> 205.34 | D35: =B35-C35 -> -75.34 | E35: =C35/B35 -> 1.5795385 | F35: =IF(C35>B35,"🔴 SUPERADO","🟢 OK") -> 🔴 SUPERADO | H35: FABI
A36: Semana 2 | B36: 130 | C36: =SUMIF($B$2:$B$31,"Semana 2",$D$2:$D$31) -> 107.61 | D36: =B36-C36 -> 22.39 | E36: =C36/B36 -> 0.82776923 | F36: =IF(C36>B36,"🔴 SUPERADO","🟢 OK") -> 🟢 OK | H36: FABI
A37: Semana 3 | B37: 130 | C37: =SUMIF($B$2:$B$31,"Semana 3",$D$2:$D$31) -> 124.4 | D37: =B37-C37 -> 5.6 | E37: =C37/B37 -> 0.95692308 | F37: =IF(C37>B37,"🔴 SUPERADO","🟢 OK") -> 🟢 OK | H37: FABI
A38: Semana 4 | B38: 130 | C38: =SUMIF($B$2:$B$31,"Semana 4",$D$2:$D$31) -> 101.74 | D38: =B38-C38 -> 28.26 | E38: =C38/B38 -> 0.78261538 | F38: =IF(C38>B38,"🔴 SUPERADO","🟢 OK") -> 🟢 OK | H38: FABI
A39: TOTAL MES | B39: =SUM(B35:B38) -> 520 | C39: =SUM(C35:C38) -> 539.09 | D39: =B39-C39 -> -19.09 | E39: =C39/B39 -> 1.0367115 | F39: =IF(C39>B39,"🔴 SUPERADO","✅ AHORRO") -> 🔴 SUPERADO
A41: INDICADORES DE RENDIMIENTO | B41: VALOR
A42: Gasto Total Real | B42: =SUM(D2:D31) -> 539.09
A43: Presupuesto Total | B43: =SUM(B35:B38) -> 520
A44: Ahorro Total | B44: =+B43-B42 -> -19.09
A45: % Ahorro Mensual | B45: =B44/B43 -> -0.036711538
A46: % Ejecución Presupuesto | B46: =1-B45 -> 1.0367115
...

Sheet GASTOS DE ROPA-CALZADO
A1: FECHA | B1: SEMANA | C1: CONCEPTO | D1: IMPORTE | E1: TARJETA | F1: CATEGORIA
A2: 46251 | B2: Semana 3 | C2: LEFTIES PETRER (PATALON BLANCO) | D2: 15.99 | E2: DEBIT | F2: ROPA Y CALZADO
A3: 46253 | B3: Semana 3 | C3: MODA VICTORIA (CHINOS-MALETA) | D3: 5 | E3: DEBIT | F3: ROPA Y CALZADO
A4: 46253 | B4: Semana 4 | C4: MODA SOPHIE (GITANA-CALZADO COCHO) | D4: 5.5 | E4: DEBIT | F4: ROPA Y CALZADO
A5: 46254 | B5: Semana 4 | C5: ZARA ALICANTE GRAN VIA (CALZADO MUCHACHAS) | D5: 28.98 | E5: DEBIT | F5: ROPA Y CALZADO
C6: Total | D6: =SUM(D2:D5) -> 55.47

Sheet GASTOS-TARJETA CREDITO
A1: FECHA | B1: SEMANA | C1: CONCEPTO | D1: IMPORTE | E1: TIPO | F1: CATEGORIA
A2: 46240 | B2: Semana 1 | C2: PICHINCHA ENVIOS (Préstamo 1) | D2: 437 | E2: Préstamo Temporal | F2: Prestamo
A3: 46247 | B3: Semana 2 | C3: PICHINCHA ENVIOS (Préstamo 2) | D3: 437 | E3: Préstamo Temporal | F3: Prestamo
A4: 46261 | B4: Semana 4 | C4: REINTEGRO PICHINCHA 1 | D4: -437 | E4: Reintegro | F4: Prestamo
A5: 46265 | B5: Semana 4 | C5: REINTEGRO PICHINCHA 2 | D5: -437 | E5: Reintegro | F5: Prestamo
C6: GASTOS CON TARJETA CREDITO | D6: =SUM(D2:D3) -> 874
A7: VALORACIÓN SEMANAL | B7: TOTAL_SEMANA | C7: PRESTAMOS A YAYO DE TARJETA | D7: GASTO_REAL | E7: REINTEGROS | F7: SALDO_NETO
A8: Semana 1 | B8: =SUMIF($B$2:$B$5,"Semana 1",$D$2:$D$5) -> 437 | C8: =SUMIFS($D$2:$D$5,$B$2:$B$5,"Semana 1",$E$2:$E$5,"Préstamo Temporal") -> 437 | D8: =SUMIFS($D$2:$D$5,$B$2:$B$5,"Semana 1",$E$2:$E$5,"Gasto Real") -> 0 | E8: =SUMIFS($D$2:$D$5,$B$2:$B$5,"Semana 1",$E$2:$E$5,"Reintegro") -> 0 | F8: =B8-C8+D8 -> 0
A9: Semana 2 | B9: =SUMIF($B$2:$B$5,"Semana 2",$D$2:$D$5) -> 437 | C9: =SUMIFS($D$2:$D$5,$B$2:$B$5,"Semana 2",$E$2:$E$5,"Préstamo Temporal") -> 437 | D9: =SUMIFS($D$2:$D$5,$B$2:$B$5,"Semana 2",$E$2:$E$5,"Gasto Real") -> 0 | E9: =SUMIFS($D$2:$D$5,$B$2:$B$5,"Semana 2",$E$2:$E$5,"Reintegro") -> 0 | F9: =B9-C9+D9 -> 0
A10: Semana 3 | B10: =SUMIF($B$2:$B$5,"Semana 3",$D$2:$D$5) -> 0 | C10: =SUMIFS($D$2:$D$5,$B$2:$B$5,"Semana 3",$E$2:$E$5,"Préstamo Temporal") -> 0 | D10: =SUMIFS($D$2:$D$5,$B$2:$B$5,"Semana 3",$E$2:$E$5,"Gasto Real") -> 0 | E10: =SUMIFS($D$2:$D$5,$B$2:$B$5,"Semana 3",$E$2:$E$5,"Reintegro") -> 0 | F10: =B10-C10+D10 -> 0
A11: Semana 4 | B11: =SUMIF($B$2:$B$5,"Semana 4",$D$2:$D$5) -> -874 | C11: =SUMIFS($D$2:$D$5,$B$2:$B$5,"Semana 4",$E$2:$E$5,"Préstamo Temporal") -> 0 | D11: =SUMIFS($D$2:$D$5,$B$2:$B$5,"Semana 4",$E$2:$E$5,"Gasto Real") -> 0 | E11: =SUMIFS($D$2:$D$5,$B$2:$B$5,"Semana 4",$E$2:$E$5,"Reintegro") -> -874 | F11: =B11-C11+D11 -> -874
A12: TOTAL MES | B12: =SUM(B8:B11) -> 0 | C12: =SUM(C8:C11) -> 874 | D12: =SUM(D8:D11) -> 0 | E12: =SUM(E8:E11) -> -874 | F12: =B12-C12+D12 -> -874
A14: INDICADORES POR CATEGORÍA | B14: TOTAL_GASTO | C14: FORMULA
A15: GASOLINA | B15: =SUMIF($F$2:$F$5,"Gasolina",$D$2:$D$5) -> 0 | C15: Suma solo gasolina
A16: RESTAURANTE | B16: =SUMIF($F$2:$F$5,"Restaurante",$D$2:$D$5) -> 0 | C16: Suma solo restaurantes
A17: TOTAL GASTO REAL | B17: =D15+D16 -> 0 | C17: Suma de todas las categorías reales
A18: PRÉSTAMOS TOTALES | B18: =SUMIF($E$2:$E$5,"Préstamo Temporal",$D$2:$D$5) -> 874 | C18: Suma préstamos solicitados
A19: REINTEGROS TOTALES | B19: =SUMIF($E$2:$E$5,"Reintegro",$D$2:$D$5) -> -874 | C19: Suma reintegros (negativos)
A20: SALDO PRÉSTAMOS | B20: =D18+D19 -> 0 | C20: Debe ser 0 si se reintegró todo
A21: LÍMITE MYCARD UTILIZADO | B21: =D17 -> 0 | C21: Solo gasto real (no préstamos)

Sheet GASTOS-SALUD
A1: FECHA | B1: CONCEPTO | C1: IMPORTE | D1: MEDIO_PAGO | E1: TIPO
A2: 46240 | B2: FCIA MARI PLAZA MAYOR | C2: 15.9 | D2: Debit | E2: Salud
A3: 46247 | B3: FARMACIA HORTENSIA RICO | C3: 3.95 | D3: Debit | E3: Salud
C4: =SUM(C2:C3) -> 19.85

Sheet GASTO-GASOLINA
A1: SEMANA | B1: FECHA | C1: CONCEPTO | D1: IMPORTE | E1: MEDIO-PAGO | F1: TIPO
A2: Semana 1 | B2: 46237 | C2: GM OIL ALACANT | D2: 60 | E2: Debit | F2: Gasolina
A3: Semana 1 | B3: 46242 | C3: ES RIU MAGRE | D3: 59.85 | E3: MyCard | F3: Gasolina
A4: Semana 1 | B4: 46242 | C4: PARKING TORRENT | D4: 3.2 | E4: Debit | F4: Parking
A5: Semana 2 | B5: 46248 | C5: BEROIL L'ALFAS DEL PI | D5: 50 | E5: Debit | F5: Gasolina
A6: Semana 3 | B6: 8/20/2026 | C6: PETROALACANT VILLAFRANQUESA | D6: 50 | E6: MyCard | F6: Gasolina
A7: Semana 3 | B7: 8/22/2026 | C7: PETRER | D7: 50 | E7: Debit | F7: Gasolina
A8: Semana 4 | B8: 8/26/2026 | C8: APARC VICENTE INGLADA | D8: 7.2 | E8: MyCard | F8: Parking
A9: Semana 4 | B9: 8/28/2026 | C9: PARKING ALFONSO EL SABIO | D9: 3.7 | E9: Debit | F9: Parking
A10: Semana 4 | B10: 8/28/2026 | C10: AUTOPISTA DEL SURESTE (AU) | D10: 5.103 | E10: Debit | F10: Parking
C11: TOTAL SUMA MES | D11: =SUM(D2:D10) -> 289.053
A12: RESUMEN SEMANAL | B12: PRESUPUESTO CARGA COMBUSTIBLE | C12: GASTADO | D12: DIFERENCIA | E12: ESTADO
A13: Semana 1 | B13: 50 | C13: =SUMIF(A2:A10,"Semana 1",$D$2:$D$10) -> 123.05 | D13: =B13-C13 -> -73.05 | E13: =IF(C13>B13," SUPERADO","🟢 OK") -> SUPERADO
A14: Semana 2 | B14: 50 | C14: =SUMIF(A2:A10,"Semana 2",$D$2:$D$10) -> 50 | D14: =B14-C14 -> 0 | E14: =IF(C14>B14,"🔴 SUPERADO","🟢 OK") -> 🟢 OK
A15: Semana 3 | B15: 50 | C15: =SUMIF(A2:A10,"Semana 3",$D$2:$D$10) -> 100 | D15: =B15-C15 -> -50 | E15: =IF(C15>B15,"🔴 SUPERADO","🟢 OK") -> 🔴 SUPERADO
A16: Semana 4 | B16: 50 | C16: =SUMIF(A2:A10,"Semana 4",$D$2:$D$10) -> 16.003 | D16: =B16-C16 -> 33.997 | E16: =IF(C16>B16,"🔴 SUPERADO","🟢 OK") -> 🟢 OK
A17: TOTAL MES | B17: =SUM(B13:B16) -> 200 | C17: =SUM(C13:C16) -> 289.053 | D17: =B17-C17 -> -89.053 | E17: =IF(C17>B17,"🔴 SUPERADO","✅ AHORRO") -> 🔴 SUPERADO

Sheet GASTO RESTAURANT
A1: FECHA | B1: SEMANA | C1: CONCEPTO | D1: IMPORTE | E1: TIPO | F1: MEDIO-PAGO | G1: BANCO | H1: CATEGORIA
A2: 46236 | B2: Semana 1 | C2: RESTAURANTE LAVASH KEBAP | D2: 24 | E2: Gasto Real | F2: Debit | G2: CAIXABANK | H2: Restaurante
A3: 46243 | B3: Semana 2 | C3: RESTAURANTE LAVASH KEBAP | D3: 20.5 | E3: Gasto Real | F3: MyCard | G3: CAIXABANK | H3: Restaurante
A4: 8/15/2026 | B4: Semana 2 | C4: RESTAURANTE LAVASH KEBAP | D4: 24.5 | E4: Gasto Real | F4: Debit | G4: CAIXABANK | H4: Restaurante
A5: 8/20/2026 | B5: Semana 3 | C5: ZONA 3 PUKA PUKA | D5: 6 | E5: Gasto Real | F5: Debit | G5: CAIXABANK | H5: Restaurante
A6: 8/20/2026 | B6: Semana 3 | C6: LLAO LLAO GRAN VIA ALICANTE | D6: 4.75 | E6: Gasto Real | F6: Debit | G6: CAIXABANK | H6: Restaurante
A7: 8/22/2026 | B7: Semana 3 | C7: BAR ASSOCIACIO EL MORO | D7: 4 | E7: Gasto Real | F7: Debit | G7: CAIXABANK | H7: Restaurante
A8: 8/26/2026 | B8: Semana 4 | C8: CHURRERIA CALDERON | D8: 5 | E8: Gasto Real | F8: Debit | G8: CAIXABANK | H8: Restaurante
A10: RESUMEN SEMANAL | B10: PRESUPUESTO CARGA COMBUSTIBLE | C10: GASTADO | D10: DIFERENCIA | E10: ESTADO
A11: Semana 1 | B11: 25 | C11: =SUMIF($B$2:$B$8,"Semana 1",$D$2:$D$8) -> 24 | D11: =B11-C11 -> 1 | E11: =IF(C11>B11," SUPERADO","🟢 OK") -> 🟢 OK
A12: Semana 2 | B12: 25 | C12: =SUMIF($B$2:$B$8,"Semana 2",$D$2:$D$8) -> 45 | D12: =B12-C12 -> -20 | E12: =IF(C12>B12,"🔴 SUPERADO","🟢 OK") -> 🔴 SUPERADO
A13: Semana 3 | B13: 25 | C13: =SUMIF($B$2:$B$8,"Semana 3",$D$2:$D$8) -> 14.75 | D13: =B13-C13 -> 10.25 | E13: =IF(C13>B13,"🔴 SUPERADO","🟢 OK") -> 🟢 OK
A14: Semana 4 | B14: 25 | C14: =SUMIF($B$2:$B$8,"Semana 4",$D$2:$D$8) -> 5 | D14: =B14-C14 -> 20 | E14: =IF(C14>B14,"🔴 SUPERADO","🟢 OK") -> 🟢 OK
A15: TOTAL MES | B15: =SUM(B11:B14) -> 100 | C15: =SUM(C11:C14) -> 88.75 | D15: =B15-C15 -> 11.25 | E15: =IF(C15>B15,"🔴 SUPERADO","✅ AHORRO") -> ✅ AHORRO

Sheet GASTO BIENESTAR Y BELLEZA
A1: FECHA | B1: CONCEPTO | C1: IMPORTE | D1: TIPO | E1: MEDIO-PAGO | F1: CATEGORIA
A2: 46239 | B2: RAICAR FITNESS CENTER | C2: 41 | D2: Gasto Real | E2: Debit | F2: GYM
A3: 46254 | B3: CLUB DE SURF ALHOA SPORT | C3: 24 | D3: Gasto Real | E3: Debit | F3: PADEL SURF
A4: 46254 | B4: CLUB DE SURF ALHOA SPORT | C4: 12 | D4: Gasto Real | E4: Debit | F4: PADEL SURF
C5: =SUM(C2:C4) -> 77

Sheet GASTOS SEGUROS-MUTUAS
A1: FECHA | B1: MES | C1: CONCEPTO | D1: IMPORTE | E1: TIPO | F1: MEDIO-PAGO | G1: CATEGORIA
A2: 46235 | B2: AGOSTO | C2: VIDACAIXA MYBOX AGRUPADO | D2: 26.38 | E2: Gasto Real | F2: Debit | G2: SEGURO DE VIDA
A3: 46235 | B3: AGOSTO | C3: SEGURO ADESLAS HOGAR AGRUPADO | D3: 35.14 | E3: Gasto Real | F3: Debit | G3: SEGURO DE HOGAR
A4: 46238 | B4: AGOSTO | C4: DKV SEGURO | D4: 25.5 | E4: Gasto Real | F4: Debit | G4: SEGURO DE SALUD FAMILIAR
C5: TOTAL | D5: =SUM(D2:D4) -> 87.02

Sheet GASTOS TRANSFERENCIAS
A1: FECHA | B1: SEMANA | C1: CONCEPTO | D1: IMPORTE | E1: TIPO | F1: MEDIO-PAGO | G1: BANCO | H1: CATEGORIA
A2: 46238 | B2: Semana 1 | C2: LUZ JULIO | D2: 40 | E2: Gasto Real | F2: TRANSFERENCIA BANCARIA | G2: CAIXABANK A BBVA | H2: GASTOS
A3: 46239 | B3: Semana 1 | C3: COMUNIDAD PISO TENERIA | D3: 25 | E3: Gasto Real | F3: TRANSFERENCIA BANCARIA | G3: CAIXABANK A SABADELL | H3: COMUNIDAD EDIF
A4: 46242 | B4: Semana 1 | C4: VIRGEN DEL CISNE | D4: 40 | E4: Gasto Real | F4: TRANSFERENCIA BANCARIA | G4: CAIXABANK A BBVA | H4: GASTOS
A5: 46242 | B5: Semana 1 | C5: COMIDA DIA | D5: 20 | E5: Gasto Real | F5: TRANSFERENCIA BANCARIA | G5: CAIXABANK A BBVA | H5: GASTOS
C6: TOTAL | D6: =SUM(D2:D5) -> 125

Sheet SEGURO COCHES
A1: Seguro de coche | B1: VALOR MES | C1: MESES | D1: TOTAL
A2: Seguro Seat Ibiza (prorrateado) | B2: 19.24 | C2: 12 | D2: =+B2*C2 -> 230.88
A3: Seguro KIA Mapfre (prorrateado) | B3: 29.17 | C3: 6 | D3: =+B3*C3 -> 175.02

Sheet GRAFICAS
A1: FINANZAS TIGRE — GRÁFICAS
A2: Generado automáticamente a partir de las hojas de datos de este libro (actualizado con las nuevas categorías).
